=============================================================================================
error at 2018-02-24 18:20:39 UTC
=============================================================================================
error in: control
error type: FLASH FAILURE
exception: (<class 'KeyboardInterrupt'>, KeyboardInterrupt(), <traceback object at 0x111be9608>)


Traceback (most recent call last):
  File "/Users/hectortorres/Dropbox/5 projects/1 information/1 information collection/0 operations/2 development/codebase/information_dashboard/control.py", line 153, in <module>
    rss.rss_parser(url)
  File "/Users/hectortorres/Dropbox/5 projects/1 information/1 information collection/0 operations/2 development/codebase/information_dashboard/collection/batch_collectors/rss_collector.py", line 65, in rss_parser
    feed = self.rss_ingestor(rss_url)
  File "/Users/hectortorres/Dropbox/5 projects/1 information/1 information collection/0 operations/2 development/codebase/information_dashboard/collection/batch_collectors/rss_collector.py", line 24, in rss_ingestor
    parser = feedparser.parse(rss_url, modified=last_modified)
  File "/Users/hectortorres/Library/Python/3.5/lib/python/site-packages/feedparser.py", line 3841, in parse
    f = _open_resource(url_file_stream_or_string, etag, modified, agent, referrer, handlers, request_headers)
  File "/Users/hectortorres/Library/Python/3.5/lib/python/site-packages/feedparser.py", line 2866, in _open_resource
    return opener.open(request)
  File "/Library/Frameworks/Python.framework/Versions/3.5/lib/python3.5/urllib/request.py", line 466, in open
    response = self._open(req, data)
  File "/Library/Frameworks/Python.framework/Versions/3.5/lib/python3.5/urllib/request.py", line 484, in _open
    '_open', req)
  File "/Library/Frameworks/Python.framework/Versions/3.5/lib/python3.5/urllib/request.py", line 444, in _call_chain
    result = func(*args)
  File "/Library/Frameworks/Python.framework/Versions/3.5/lib/python3.5/urllib/request.py", line 1282, in http_open
    return self.do_open(http.client.HTTPConnection, req)
  File "/Library/Frameworks/Python.framework/Versions/3.5/lib/python3.5/urllib/request.py", line 1257, in do_open
    r = h.getresponse()
  File "/Library/Frameworks/Python.framework/Versions/3.5/lib/python3.5/http/client.py", line 1197, in getresponse
    response.begin()
  File "/Library/Frameworks/Python.framework/Versions/3.5/lib/python3.5/http/client.py", line 297, in begin
    version, status, reason = self._read_status()
  File "/Library/Frameworks/Python.framework/Versions/3.5/lib/python3.5/http/client.py", line 258, in _read_status
    line = str(self.fp.readline(_MAXLINE + 1), "iso-8859-1")
  File "/Library/Frameworks/Python.framework/Versions/3.5/lib/python3.5/socket.py", line 575, in readinto
    return self._sock.recv_into(b)
KeyboardInterrupt




=============================================================================================
error at 2018-02-24 18:26:43 UTC
=============================================================================================
error in: control
error type: FLASH FAILURE
exception: (<class 'KeyboardInterrupt'>, KeyboardInterrupt(), <traceback object at 0x111ea6e48>)


Traceback (most recent call last):
  File "/Users/hectortorres/Dropbox/5 projects/1 information/1 information collection/0 operations/2 development/codebase/information_dashboard/control.py", line 153, in <module>
    rss.rss_parser(url)
  File "/Users/hectortorres/Dropbox/5 projects/1 information/1 information collection/0 operations/2 development/codebase/information_dashboard/collection/batch_collectors/rss_collector.py", line 180, in rss_parser
    urls = c.fetchall()
KeyboardInterrupt




=============================================================================================
error at 2018-02-24 19:29:36 UTC
=============================================================================================
error in: control
error type: FLASH FAILURE
exception: (<class 'KeyboardInterrupt'>, KeyboardInterrupt(), <traceback object at 0x111f08948>)


Traceback (most recent call last):
  File "/Users/hectortorres/Dropbox/5 projects/1 information/1 information collection/0 operations/2 development/codebase/information_dashboard/control.py", line 155, in <module>
    rss.rss_parser(url)
  File "/Users/hectortorres/Dropbox/5 projects/1 information/1 information collection/0 operations/2 development/codebase/information_dashboard/collection/batch_collectors/rss_collector.py", line 65, in rss_parser
    feed = self.rss_ingestor(rss_url)
  File "/Users/hectortorres/Dropbox/5 projects/1 information/1 information collection/0 operations/2 development/codebase/information_dashboard/collection/batch_collectors/rss_collector.py", line 27, in rss_ingestor
    parser = feedparser.parse(rss_url)
  File "/Users/hectortorres/Library/Python/3.5/lib/python/site-packages/feedparser.py", line 3841, in parse
    f = _open_resource(url_file_stream_or_string, etag, modified, agent, referrer, handlers, request_headers)
  File "/Users/hectortorres/Library/Python/3.5/lib/python/site-packages/feedparser.py", line 2866, in _open_resource
    return opener.open(request)
  File "/Library/Frameworks/Python.framework/Versions/3.5/lib/python3.5/urllib/request.py", line 472, in open
    response = meth(req, response)
  File "/Library/Frameworks/Python.framework/Versions/3.5/lib/python3.5/urllib/request.py", line 582, in http_response
    'http', request, response, code, msg, hdrs)
  File "/Library/Frameworks/Python.framework/Versions/3.5/lib/python3.5/urllib/request.py", line 504, in error
    result = self._call_chain(*args)
  File "/Library/Frameworks/Python.framework/Versions/3.5/lib/python3.5/urllib/request.py", line 444, in _call_chain
    result = func(*args)
  File "/Users/hectortorres/Library/Python/3.5/lib/python/site-packages/feedparser.py", line 2766, in http_error_301
    code, msg, hdrs)
  File "/Library/Frameworks/Python.framework/Versions/3.5/lib/python3.5/urllib/request.py", line 696, in http_error_302
    return self.parent.open(new, timeout=req.timeout)
  File "/Library/Frameworks/Python.framework/Versions/3.5/lib/python3.5/urllib/request.py", line 466, in open
    response = self._open(req, data)
  File "/Library/Frameworks/Python.framework/Versions/3.5/lib/python3.5/urllib/request.py", line 484, in _open
    '_open', req)
  File "/Library/Frameworks/Python.framework/Versions/3.5/lib/python3.5/urllib/request.py", line 444, in _call_chain
    result = func(*args)
  File "/Library/Frameworks/Python.framework/Versions/3.5/lib/python3.5/urllib/request.py", line 1297, in https_open
    context=self._context, check_hostname=self._check_hostname)
  File "/Library/Frameworks/Python.framework/Versions/3.5/lib/python3.5/urllib/request.py", line 1257, in do_open
    r = h.getresponse()
  File "/Library/Frameworks/Python.framework/Versions/3.5/lib/python3.5/http/client.py", line 1197, in getresponse
    response.begin()
  File "/Library/Frameworks/Python.framework/Versions/3.5/lib/python3.5/http/client.py", line 297, in begin
    version, status, reason = self._read_status()
  File "/Library/Frameworks/Python.framework/Versions/3.5/lib/python3.5/http/client.py", line 258, in _read_status
    line = str(self.fp.readline(_MAXLINE + 1), "iso-8859-1")
  File "/Library/Frameworks/Python.framework/Versions/3.5/lib/python3.5/socket.py", line 575, in readinto
    return self._sock.recv_into(b)
  File "/Library/Frameworks/Python.framework/Versions/3.5/lib/python3.5/ssl.py", line 929, in recv_into
    return self.read(nbytes, buffer)
  File "/Library/Frameworks/Python.framework/Versions/3.5/lib/python3.5/ssl.py", line 791, in read
    return self._sslobj.read(len, buffer)
  File "/Library/Frameworks/Python.framework/Versions/3.5/lib/python3.5/ssl.py", line 575, in read
    v = self._sslobj.read(len, buffer)
KeyboardInterrupt




=============================================================================================
error at 2018-02-24 19:30:04 UTC
=============================================================================================
error in: control
error type: FLASH FAILURE
exception: (<class 'KeyboardInterrupt'>, KeyboardInterrupt(), <traceback object at 0x10f9b62c8>)


Traceback (most recent call last):
  File "/Users/hectortorres/Dropbox/5 projects/1 information/1 information collection/0 operations/2 development/codebase/information_dashboard/control.py", line 155, in <module>
    rss.rss_parser(url)
  File "/Users/hectortorres/Dropbox/5 projects/1 information/1 information collection/0 operations/2 development/codebase/information_dashboard/collection/batch_collectors/rss_collector.py", line 65, in rss_parser
    feed = self.rss_ingestor(rss_url)
  File "/Users/hectortorres/Dropbox/5 projects/1 information/1 information collection/0 operations/2 development/codebase/information_dashboard/collection/batch_collectors/rss_collector.py", line 27, in rss_ingestor
    parser = feedparser.parse(rss_url)
  File "/Users/hectortorres/Library/Python/3.5/lib/python/site-packages/feedparser.py", line 3841, in parse
    f = _open_resource(url_file_stream_or_string, etag, modified, agent, referrer, handlers, request_headers)
  File "/Users/hectortorres/Library/Python/3.5/lib/python/site-packages/feedparser.py", line 2866, in _open_resource
    return opener.open(request)
  File "/Library/Frameworks/Python.framework/Versions/3.5/lib/python3.5/urllib/request.py", line 466, in open
    response = self._open(req, data)
  File "/Library/Frameworks/Python.framework/Versions/3.5/lib/python3.5/urllib/request.py", line 484, in _open
    '_open', req)
  File "/Library/Frameworks/Python.framework/Versions/3.5/lib/python3.5/urllib/request.py", line 444, in _call_chain
    result = func(*args)
  File "/Library/Frameworks/Python.framework/Versions/3.5/lib/python3.5/urllib/request.py", line 1282, in http_open
    return self.do_open(http.client.HTTPConnection, req)
  File "/Library/Frameworks/Python.framework/Versions/3.5/lib/python3.5/urllib/request.py", line 1257, in do_open
    r = h.getresponse()
  File "/Library/Frameworks/Python.framework/Versions/3.5/lib/python3.5/http/client.py", line 1197, in getresponse
    response.begin()
  File "/Library/Frameworks/Python.framework/Versions/3.5/lib/python3.5/http/client.py", line 297, in begin
    version, status, reason = self._read_status()
  File "/Library/Frameworks/Python.framework/Versions/3.5/lib/python3.5/http/client.py", line 258, in _read_status
    line = str(self.fp.readline(_MAXLINE + 1), "iso-8859-1")
  File "/Library/Frameworks/Python.framework/Versions/3.5/lib/python3.5/socket.py", line 575, in readinto
    return self._sock.recv_into(b)
KeyboardInterrupt




=============================================================================================
error at 2018-02-24 19:34:22 UTC
=============================================================================================
error in: stock_ingestor
error type: Alpha Vantage API call
exception: (<class 'pandas.errors.ParserError'>, ParserError('Error tokenizing data. C error: Expected 1 fields in line 4, saw 2\n',), <traceback object at 0x101e2b648>)


Traceback (most recent call last):
  File "/Users/hectortorres/Dropbox/5 projects/1 information/1 information collection/0 operations/2 development/codebase/information_dashboard/collection/batch_collectors/stock_collector.py", line 56, in stock_ingestor
    stocks_df = pandas.read_csv(StringIO(stocks_str))
  File "/Library/Frameworks/Python.framework/Versions/3.5/lib/python3.5/site-packages/pandas/io/parsers.py", line 709, in parser_f
    return _read(filepath_or_buffer, kwds)
  File "/Library/Frameworks/Python.framework/Versions/3.5/lib/python3.5/site-packages/pandas/io/parsers.py", line 455, in _read
    data = parser.read(nrows)
  File "/Library/Frameworks/Python.framework/Versions/3.5/lib/python3.5/site-packages/pandas/io/parsers.py", line 1069, in read
    ret = self._engine.read(nrows)
  File "/Library/Frameworks/Python.framework/Versions/3.5/lib/python3.5/site-packages/pandas/io/parsers.py", line 1839, in read
    data = self._reader.read(nrows)
  File "pandas/_libs/parsers.pyx", line 902, in pandas._libs.parsers.TextReader.read
  File "pandas/_libs/parsers.pyx", line 924, in pandas._libs.parsers.TextReader._read_low_memory
  File "pandas/_libs/parsers.pyx", line 978, in pandas._libs.parsers.TextReader._read_rows
  File "pandas/_libs/parsers.pyx", line 965, in pandas._libs.parsers.TextReader._tokenize_rows
  File "pandas/_libs/parsers.pyx", line 2208, in pandas._libs.parsers.raise_parser_error
pandas.errors.ParserError: Error tokenizing data. C error: Expected 1 fields in line 4, saw 2





